2018-06-14 14:14:17,907 ERROR: Exception on /auth/login [GET] [in /usr/local/lib/python3.5/dist-packages/flask/app.py:1761]
Traceback (most recent call last):
  File "/usr/local/lib/python3.5/dist-packages/flask/app.py", line 2292, in wsgi_app
    response = self.full_dispatch_request()
  File "/usr/local/lib/python3.5/dist-packages/flask/app.py", line 1815, in full_dispatch_request
    rv = self.handle_user_exception(e)
  File "/usr/local/lib/python3.5/dist-packages/flask/app.py", line 1718, in handle_user_exception
    reraise(exc_type, exc_value, tb)
  File "/usr/local/lib/python3.5/dist-packages/flask/_compat.py", line 35, in reraise
    raise value
  File "/usr/local/lib/python3.5/dist-packages/flask/app.py", line 1813, in full_dispatch_request
    rv = self.dispatch_request()
  File "/usr/local/lib/python3.5/dist-packages/flask/app.py", line 1799, in dispatch_request
    return self.view_functions[rule.endpoint](**req.view_args)
  File "/mnt/d/Code/microblog/app/auth/routes.py", line 26, in login
    return render_template('auth/login.html', title=_('Sign In'), form=form)
  File "/usr/local/lib/python3.5/dist-packages/flask/templating.py", line 135, in render_template
    context, ctx.app)
  File "/usr/local/lib/python3.5/dist-packages/flask/templating.py", line 117, in _render
    rv = template.render(context)
  File "/usr/local/lib/python3.5/dist-packages/jinja2/environment.py", line 1008, in render
    return self.environment.handle_exception(exc_info, True)
  File "/usr/local/lib/python3.5/dist-packages/jinja2/environment.py", line 780, in handle_exception
    reraise(exc_type, exc_value, tb)
  File "/usr/local/lib/python3.5/dist-packages/jinja2/_compat.py", line 37, in reraise
    raise value.with_traceback(tb)
  File "/mnt/d/Code/microblog/app/templates/auth/login.html", line 2, in top-level template code
    {% import 'bootstrap/wtf.html' as wtf %}
  File "/mnt/d/Code/microblog/app/templates/base.html", line 1, in top-level template code
    {% extends 'bootstrap/base.html' %}
  File "/usr/local/lib/python3.5/dist-packages/flask_bootstrap/templates/bootstrap/base.html", line 1, in top-level template code
    {% block doc -%}
  File "/usr/local/lib/python3.5/dist-packages/flask_bootstrap/templates/bootstrap/base.html", line 4, in block "doc"
    {%- block html %}
  File "/usr/local/lib/python3.5/dist-packages/flask_bootstrap/templates/bootstrap/base.html", line 20, in block "html"
    {% block body -%}
  File "/usr/local/lib/python3.5/dist-packages/flask_bootstrap/templates/bootstrap/base.html", line 21, in block "body"
    {% block navbar %}
  File "/mnt/d/Code/microblog/app/templates/base.html", line 26, in block "navbar"
    {% set new_messages = current_user.new_messages() %}
jinja2.exceptions.UndefinedError: 'flask_login.mixins.AnonymousUserMixin object' has no attribute 'new_messages'
2018-06-14 14:14:45,707 ERROR: Exception on /auth/login [GET] [in /usr/local/lib/python3.5/dist-packages/flask/app.py:1761]
Traceback (most recent call last):
  File "/usr/local/lib/python3.5/dist-packages/flask/app.py", line 2292, in wsgi_app
    response = self.full_dispatch_request()
  File "/usr/local/lib/python3.5/dist-packages/flask/app.py", line 1815, in full_dispatch_request
    rv = self.handle_user_exception(e)
  File "/usr/local/lib/python3.5/dist-packages/flask/app.py", line 1718, in handle_user_exception
    reraise(exc_type, exc_value, tb)
  File "/usr/local/lib/python3.5/dist-packages/flask/_compat.py", line 35, in reraise
    raise value
  File "/usr/local/lib/python3.5/dist-packages/flask/app.py", line 1813, in full_dispatch_request
    rv = self.dispatch_request()
  File "/usr/local/lib/python3.5/dist-packages/flask/app.py", line 1799, in dispatch_request
    return self.view_functions[rule.endpoint](**req.view_args)
  File "/mnt/d/Code/microblog/app/auth/routes.py", line 26, in login
    return render_template('auth/login.html', title=_('Sign In'), form=form)
  File "/usr/local/lib/python3.5/dist-packages/flask/templating.py", line 135, in render_template
    context, ctx.app)
  File "/usr/local/lib/python3.5/dist-packages/flask/templating.py", line 117, in _render
    rv = template.render(context)
  File "/usr/local/lib/python3.5/dist-packages/jinja2/environment.py", line 1008, in render
    return self.environment.handle_exception(exc_info, True)
  File "/usr/local/lib/python3.5/dist-packages/jinja2/environment.py", line 780, in handle_exception
    reraise(exc_type, exc_value, tb)
  File "/usr/local/lib/python3.5/dist-packages/jinja2/_compat.py", line 37, in reraise
    raise value.with_traceback(tb)
  File "/mnt/d/Code/microblog/app/templates/auth/login.html", line 2, in top-level template code
    {% import 'bootstrap/wtf.html' as wtf %}
  File "/mnt/d/Code/microblog/app/templates/base.html", line 1, in top-level template code
    {% extends 'bootstrap/base.html' %}
  File "/usr/local/lib/python3.5/dist-packages/flask_bootstrap/templates/bootstrap/base.html", line 1, in top-level template code
    {% block doc -%}
  File "/usr/local/lib/python3.5/dist-packages/flask_bootstrap/templates/bootstrap/base.html", line 4, in block "doc"
    {%- block html %}
  File "/usr/local/lib/python3.5/dist-packages/flask_bootstrap/templates/bootstrap/base.html", line 20, in block "html"
    {% block body -%}
  File "/usr/local/lib/python3.5/dist-packages/flask_bootstrap/templates/bootstrap/base.html", line 21, in block "body"
    {% block navbar %}
  File "/mnt/d/Code/microblog/app/templates/base.html", line 26, in block "navbar"
    {% set new_messages = current_user.new_messages() %}
jinja2.exceptions.UndefinedError: 'flask_login.mixins.AnonymousUserMixin object' has no attribute 'new_messages'
2018-06-14 14:14:52,361 ERROR: Exception on /auth/login [GET] [in /usr/local/lib/python3.5/dist-packages/flask/app.py:1761]
Traceback (most recent call last):
  File "/usr/local/lib/python3.5/dist-packages/flask/app.py", line 2292, in wsgi_app
    response = self.full_dispatch_request()
  File "/usr/local/lib/python3.5/dist-packages/flask/app.py", line 1815, in full_dispatch_request
    rv = self.handle_user_exception(e)
  File "/usr/local/lib/python3.5/dist-packages/flask/app.py", line 1718, in handle_user_exception
    reraise(exc_type, exc_value, tb)
  File "/usr/local/lib/python3.5/dist-packages/flask/_compat.py", line 35, in reraise
    raise value
  File "/usr/local/lib/python3.5/dist-packages/flask/app.py", line 1813, in full_dispatch_request
    rv = self.dispatch_request()
  File "/usr/local/lib/python3.5/dist-packages/flask/app.py", line 1799, in dispatch_request
    return self.view_functions[rule.endpoint](**req.view_args)
  File "/mnt/d/Code/microblog/app/auth/routes.py", line 26, in login
    return render_template('auth/login.html', title=_('Sign In'), form=form)
  File "/usr/local/lib/python3.5/dist-packages/flask/templating.py", line 135, in render_template
    context, ctx.app)
  File "/usr/local/lib/python3.5/dist-packages/flask/templating.py", line 117, in _render
    rv = template.render(context)
  File "/usr/local/lib/python3.5/dist-packages/jinja2/environment.py", line 1008, in render
    return self.environment.handle_exception(exc_info, True)
  File "/usr/local/lib/python3.5/dist-packages/jinja2/environment.py", line 780, in handle_exception
    reraise(exc_type, exc_value, tb)
  File "/usr/local/lib/python3.5/dist-packages/jinja2/_compat.py", line 37, in reraise
    raise value.with_traceback(tb)
  File "/mnt/d/Code/microblog/app/templates/auth/login.html", line 2, in top-level template code
    {% import 'bootstrap/wtf.html' as wtf %}
  File "/mnt/d/Code/microblog/app/templates/base.html", line 1, in top-level template code
    {% extends 'bootstrap/base.html' %}
  File "/usr/local/lib/python3.5/dist-packages/flask_bootstrap/templates/bootstrap/base.html", line 1, in top-level template code
    {% block doc -%}
  File "/usr/local/lib/python3.5/dist-packages/flask_bootstrap/templates/bootstrap/base.html", line 4, in block "doc"
    {%- block html %}
  File "/usr/local/lib/python3.5/dist-packages/flask_bootstrap/templates/bootstrap/base.html", line 20, in block "html"
    {% block body -%}
  File "/usr/local/lib/python3.5/dist-packages/flask_bootstrap/templates/bootstrap/base.html", line 21, in block "body"
    {% block navbar %}
  File "/mnt/d/Code/microblog/app/templates/base.html", line 26, in block "navbar"
    {% set new_messages = current_user.new_messages() %}
jinja2.exceptions.UndefinedError: 'flask_login.mixins.AnonymousUserMixin object' has no attribute 'new_messages'
2018-06-14 14:17:46,327 INFO: Microblog startup [in /mnt/d/Code/microblog/app/__init__.py:78]
2018-06-14 14:18:03,889 ERROR: Exception on /messages [GET] [in /usr/local/lib/python3.5/dist-packages/flask/app.py:1761]
Traceback (most recent call last):
  File "/usr/local/lib/python3.5/dist-packages/flask/app.py", line 2292, in wsgi_app
    response = self.full_dispatch_request()
  File "/usr/local/lib/python3.5/dist-packages/flask/app.py", line 1815, in full_dispatch_request
    rv = self.handle_user_exception(e)
  File "/usr/local/lib/python3.5/dist-packages/flask/app.py", line 1718, in handle_user_exception
    reraise(exc_type, exc_value, tb)
  File "/usr/local/lib/python3.5/dist-packages/flask/_compat.py", line 35, in reraise
    raise value
  File "/usr/local/lib/python3.5/dist-packages/flask/app.py", line 1813, in full_dispatch_request
    rv = self.dispatch_request()
  File "/usr/local/lib/python3.5/dist-packages/flask/app.py", line 1799, in dispatch_request
    return self.view_functions[rule.endpoint](**req.view_args)
  File "/usr/local/lib/python3.5/dist-packages/flask_login/utils.py", line 261, in decorated_view
    return func(*args, **kwargs)
  File "/mnt/d/Code/microblog/app/main/routes.py", line 173, in messages
    current_user.add_notification('unread_message_count', 0)
  File "/mnt/d/Code/microblog/app/models.py", line 117, in add_notification
    self.notificaitons.filter_by(name=name).delete()
AttributeError: 'User' object has no attribute 'notificaitons'
2018-06-14 14:18:28,203 INFO: Microblog startup [in /mnt/d/Code/microblog/app/__init__.py:78]
